<?xml version="1.0"?>
<robot xmlns:xacro="http://www.ros.org/wiki/xacro">

    <xacro:include filename="inertial_macros.xacro"/>

    <material name="white">
        <color rgba="1 1 1 1" />
    </material>

    <material name="orange">
        <color rgba="1 0.3 0.1 1" />
    </material>

    <material name="blue">
        <color rgba="0.2 0.2 1 1"/>
    </material>

    <material name="black">
        <color rgba="0 0 0 1"/>
    </material>

    <!-- BASE LINK -->
    <link name="base_link">

    </link>

    <!-- CHASSIS LINK -->
    <joint name="chassis_joint" type="fixed">
        <parent link="base_link" />
        <child link="chassis" />
        <origin xyz = "-0.1 0 0" />
    </joint>

    <link name="chassis">
        <visual>
            <origin xyz = "0.15 0 0.055" />
            <geometry>
                <box size="0.3 0.3 0.05" />
            </geometry>
            <material name="white"/>
        </visual>
        <collision>
            <origin xyz = "0.15 0 0.075" />
            <geometry>
                <box size="0.3 0.3 0.05" />
            </geometry>
        </collision>
        <xacro:inertial_box mass="0.5" x="0.3" y="0.3" z="0.15">
            <origin xyz="0.15 0 0.075" rpy="0 0 0"/>
        </xacro:inertial_box>
    </link>

    <gazebo reference="chassis">
        <material>Gazebo/Grey</material>
    </gazebo>

    <!-- LEFT WHEEL LINK -->

    <joint name ="left_wheel_joint" type="continuous">
        <parent link="base_link"/>
        <child link="left_wheel" />
        <!-- MUST ROTATE THE CYLINDER pi/2 -->
        <origin xyz="0 0.175 0" rpy="-${pi/2} 0 0" />
        <axis xyz="0 0 1"/>
    </joint>

    <link name="left_wheel">
        <visual>
            <geometry>
                <cylinder radius ="0.05" length ="0.04" />
            </geometry>
            <material name="blue"/>
        </visual>
        <collision>
            <geometry>
                <cylinder radius ="0.05" length ="0.04" />
            </geometry>
        </collision>
        <xacro:inertial_cylinder mass="0.1" length="0.04" radius="0.05">
            <origin xyz="0 0 0" rpy="0 0 0" />
        </xacro:inertial_cylinder>
    </link>

    <gazebo reference="left_wheel">
        <material>Gazebo/Blue</material>
    </gazebo>

    <!-- RIGHT WHEEL LINK -->

    <joint name ="right_wheel_joint" type="continuous">
        <parent link="base_link"/>
        <child link="right_wheel" />
        <!-- MUST ROTATE THE CYLINDER pi/2 -->
        <origin xyz="0 -0.175 0" rpy="-${pi/2} 0 0" />
        <axis xyz="0 0 -1"/>
    </joint>

    <link name="right_wheel">
        <visual>
            <geometry>
                <cylinder radius ="0.05" length ="0.04" />
            </geometry>
            <material name="blue"/>
        </visual>
        <collision>
            <geometry>
                <cylinder radius ="0.05" length ="0.04" />
            </geometry>
        </collision>
        <xacro:inertial_cylinder mass="0.1" length="0.04" radius="0.05">
            <origin xyz="0 0 0" rpy="0 0 0" />
        </xacro:inertial_cylinder>
    </link>

    <gazebo reference="right_wheel">
        <material>Gazebo/Blue</material>
    </gazebo>

    <!-- CASTER WHEEL LINK -->
    <joint name ="caster_wheel_joint" type="fixed">
        <parent link="chassis"/>
        <child link="caster_wheel"/>
        <origin xyz="0.24 0 0"/>
    </joint>

    <link name="caster_wheel">
        <visual>
            <geometry>
                <sphere radius="0.05"/>
            </geometry>
            <material name="black"/>
        </visual>
        <collision>
            <geometry>
                <sphere radius="0.05"/>
            </geometry>
        </collision>
        <xacro:inertial_sphere mass="0.1" radius="0.05">
            <origin xyz="0 0 0" rpy="0 0 0"/>
        </xacro:inertial_sphere>
    </link>

    <gazebo reference="caster_wheel">
        <material>Gazebo/Black</material>
        <mu1 value="0.001"/>
        <mu2 value="0.001" />
    </gazebo>

    <!-- LEG LINK 1 -->
    <joint name="leg1_joint" type="fixed">
        <parent link="chassis"/>
        <child link="leg1"/>
        <origin xyz="0.15 0.1 0.25"/>
    </joint>

    <link name="leg1">
        <visual>
            <origin xyz="0 0 0"/>
            <geometry>
                <cylinder radius="0.05" length="0.4"/>
            </geometry>
            <material name="orange"/>
        </visual>
        <collision>
            <origin xyz="0 0 0"/>
            <geometry>
                <cylinder radius="0.05" length="0.4"/>
            </geometry>
        </collision>
        <xacro:inertial_cylinder mass="0.05" length="0.4" radius="0.05">
            <origin xyz="0 0 0" rpy="0 0 0"/>
        </xacro:inertial_cylinder>
    </link>

    <gazebo reference="leg1">
        <material>Gazebo/Orange</material>
    </gazebo>

    <!-- LEG LINK 2 -->
    <joint name="leg2_joint" type="fixed">
        <parent link="chassis"/>
        <child link="leg2"/>
        <origin xyz="0.15 -0.1 0.25"/>
    </joint>

    <link name="leg2">
        <visual>
            <origin xyz="0 0 0"/>
            <geometry>
                <cylinder radius="0.05" length="0.4"/>
            </geometry>
            <material name="orange"/>
        </visual>
        <collision>
            <origin xyz="0 0 0"/>
            <geometry>
                <cylinder radius="0.05" length="0.4"/>
            </geometry>
        </collision>
        <xacro:inertial_cylinder mass="0.05" length="0.4" radius="0.05">
            <origin xyz="0 0 0" rpy="0 0 0"/>
        </xacro:inertial_cylinder>
    </link>

    <gazebo reference="leg2">
        <material>Gazebo/Orange</material>
    </gazebo>

    <!-- UPPER BODY LINK -->
    <joint name="upper_body_joint" type="fixed">
        <parent link="base_link"/>
        <child link="upper_body"/>
        <origin xyz="0.05 0 0.55"/>
    </joint>

    <link name="upper_body">
        <visual>
            <origin xyz="0 0 0"/>
            <geometry>
                <box size="0.1 0.3 0.35"/>
            </geometry>
            <material name="white"/>
        </visual>
        <collision>
            <origin xyz="0 0 0"/>
            <geometry>
                <box size="0.1 0.3 0.35"/>
            </geometry>
        </collision>
        <xacro:inertial_box mass="0.1" x="0.2" y="0.2" z="0.2">
            <origin xyz="0 0 0" rpy="0 0 0"/>
        </xacro:inertial_box>
    </link>

    <gazebo reference="upper_body">
        <material>Gazebo/White</material>
    </gazebo>

    <!-- HEAD LINK -->
    <joint name="head_joint" type="fixed">
        <parent link="upper_body"/>
        <child link="head"/>
        <origin xyz="0 0 0.25"/>
        <!-- Adjust the XYZ values as needed -->
    </joint>

    <link name="head">
        <visual>
            <origin xyz="0 0 0"/>
            <geometry>
                <sphere radius="0.075"/>
                <!-- Adjust the radius as needed -->
            </geometry>
            <material name="blue"/>
        </visual>
        <collision>
            <origin xyz="0 0 0"/>
            <geometry>
                <sphere radius="0.075"/>
            </geometry>
        </collision>
        <xacro:inertial_sphere mass="0.05" radius="0.1">
            <origin xyz="0 0 0" rpy="0 0 0"/>
        </xacro:inertial_sphere>
    </link>

    <gazebo reference="head">
        <material>Gazebo/Blue</material>
    </gazebo>


</robot>